Workbook
Name Print_Titles_0: Contemporary!$A$11:$IV$11
Name Print_Titles_0: Duo!$A$6:$IV$6
Name Print_Titles_0: 'Solo list'!$A$1
Name Print_Titles_0_0: Contemporary!$A$11:$IV$11
Name Print_Titles_0_0: Duo!$A$6:$IV$6
Name Print_Titles_0_0: 'Solo list'!$A$1
Name Print_Titles_0_0_0: Contemporary!$A$11:$IV$11
Name Print_Titles_0_0_0: Duo!$A$6:$IV$6
Name Print_Titles_0_0_0: 'Solo list'!$A$1
Name Print_Titles_0_0_0_0: Contemporary!$A$11:$IV$11
Name Print_Titles_0_0_0_0: Duo!$A$6:$IV$6
Name Print_Titles_0_0_0_0: 'Solo list'!$A$1
Name Print_Titles_0_0_0_0_0: Contemporary!$A$11:$IV$11
Name Print_Titles_0_0_0_0_0: Duo!$A$6:$IV$6
Name Print_Titles_0_0_0_0_0: 'Solo list'!$A$1
Name Print_Titles_0_0_0_0_0_0: Contemporary!$A$11:$IV$11
Name Print_Titles_0_0_0_0_0_0: Duo!$A$6:$IV$6
Name Print_Titles_0_0_0_0_0_0: 'Solo list'!$A$1
Name Print_Titles_0_0_0_0_0_0_0: Contemporary!$A$11:$IV$11
Name Print_Titles_0_0_0_0_0_0_0: Duo!$A$6:$IV$6
Name Print_Titles_0_0_0_0_0_0_0: 'Solo list'!$A$1
Name Print_Titles_0_0_0_0_0_0_0_0: Contemporary!$A$11:$IV$11
Name Print_Titles_0_0_0_0_0_0_0_0: Duo!$A$6:$IV$6
Name Print_Titles_0_0_0_0_0_0_0_0: 'Solo list'!$A$1
Name Print_Titles_0_0_0_0_0_0_0_0_0: Contemporary!$A$11:$IV$11
Name Print_Titles_0_0_0_0_0_0_0_0_0: Duo!$A$6:$IV$6
Name Print_Titles_0_0_0_0_0_0_0_0_0: 'Solo list'!$A$1
Name Print_Titles_0_0_0_0_0_0_0_0_0_0: Contemporary!$A$11:$IV$11
Name Print_Titles_0_0_0_0_0_0_0_0_0_0: Duo!$A$6:$IV$6
Name Print_Titles_0_0_0_0_0_0_0_0_0_0: 'Solo list'!$A$1
Name Print_Titles_0_0_0_0_0_0_0_0_0_0_0: Contemporary!$A$11:$IV$11
Name Print_Titles_0_0_0_0_0_0_0_0_0_0_0: Duo!$A$6:$IV$6
Name Print_Titles_0_0_0_0_0_0_0_0_0_0_0: 'Solo list'!$A$1
Name repertoire_csv: CSV!$A$1:$A$536
Name repertoirelist: Contemporary!$B$1:$W$324
Name Table1: #REF!

Sheet Contemporary
B1: WIP | C1: Key | D1: Title | E1: Artist | F1: Cover? | G1: Year | H1: Genre | I1: Genre 2 | K1: Tags | M1: Title | N1: Artist | O1: Release | P1: BPM | Q1: Energy | R1: Dance | S1: Loud | T1: Valence | U1: Length | V1: Acoustic | W1: Popularity
A3: =RAND() -> 0.81236922 | B3: WIP | C3: F#m | D3: 1973 | E3: James Blunt | G3: 2007 | H3: Rock | I3: Pop | J3: pop;alternative;love;dance | K3: =CONCATENATE(SUBSTITUTE(Spotify!J3,",",";"),";",J3) -> ;pop;alternative;love;dance | M3: =Spotify!B3 -> 1973 | N3: =Spotify!D3 -> James Blunt | O3: =Spotify!E3 -> 39330 | P3: =ROUND(Spotify!U3,0) -> 123 | Q3: =ROUND(Spotify!L3*100,0) -> 67 | R3: =ROUND(Spotify!K3*100,0) -> 72 | S3: =Spotify!N3 -> -7.928 | T3: =ROUND(Spotify!T3*100,0) -> 77 | U3: =ROUND(Spotify!F3/60000,1) -> 4.7 | V3: =ROUND(Spotify!Q3*100,0) -> 7 | W3: =Spotify!G3 -> 75
C4: G | D4: A Hard Day's Night | E4: Beatles | G4: 1964 | H4: Rock | J4: dance;jive;fast;groovy;love;oldies;retro | K4: =CONCATENATE(SUBSTITUTE(Spotify!J4,",",";"),";",J4) -> classic rock;psychedelic rock;dance;jive;fast;groovy;love;oldies;retro | M4: =Spotify!B4 -> A Hard Day's Night - Remastered 2015 | N4: =Spotify!D4 -> The Beatles | O4: =Spotify!E4 -> 36843 | P4: =ROUND(Spotify!U4,0) -> 139 | Q4: =ROUND(Spotify!L4*100,0) -> 82 | R4: =ROUND(Spotify!K4*100,0) -> 55 | S4: =Spotify!N4 -> -4.89 | T4: =ROUND(Spotify!T4*100,0) -> 76 | U4: =ROUND(Spotify!F4/60000,1) -> 2.5 | V4: =ROUND(Spotify!Q4*100,0) -> 5 | W4: =Spotify!G4 -> 54
A5: =RAND() -> 0.52698433 | B5: WIP | C5: A | D5: A Little Less Conversation | E5: Elvis Presley | G5: 1968 | H5: Rock | J5: dance;jive;fast;groovy;love;oldies;retro | K5: =CONCATENATE(SUBSTITUTE(Spotify!J5,",",";"),";",J5) -> rockabilly;rock and roll;dance;jive;fast;groovy;love;oldies;retro | M5: =Spotify!B5 -> A Little Less Conversation | N5: =Spotify!D5 -> Elvis Presley | O5: =Spotify!E5 -> 2007 | P5: =ROUND(Spotify!U5,0) -> 114 | Q5: =ROUND(Spotify!L5*100,0) -> 80 | R5: =ROUND(Spotify!K5*100,0) -> 58 | S5: =Spotify!N5 -> -8.03 | T5: =ROUND(Spotify!T5*100,0) -> 84 | U5: =ROUND(Spotify!F5/60000,1) -> 2 | V5: =ROUND(Spotify!Q5*100,0) -> 15 | W5: =Spotify!G5 -> 56
A6: =RAND() -> 0.038804632 | B6: WIP | C6: F | D6: A Little More | E6: Eric Hutchinson | G6: 2014 | H6: Rock | I6: Pop | J6: fast;dance;groovy;alternative | K6: =CONCATENATE(SUBSTITUTE(Spotify!J6,",",";"),";",J6) -> ;fast;dance;groovy;alternative | M6: =Spotify!B6 -> A Little More | N6: =Spotify!D6 -> Eric Hutchinson | O6: =Spotify!E6 -> 41737 | P6: =ROUND(Spotify!U6,0) -> 80 | Q6: =ROUND(Spotify!L6*100,0) -> 74 | R6: =ROUND(Spotify!K6*100,0) -> 64 | S6: =Spotify!N6 -> -5.084 | T6: =ROUND(Spotify!T6*100,0) -> 94 | U6: =ROUND(Spotify!F6/60000,1) -> 3.3 | V6: =ROUND(Spotify!Q6*100,0) -> 1 | W6: =Spotify!G6 -> 44
A7: =RAND() -> 0.33794738 | B7: WIP | C7: Dm | D7: A Man For All Seasons | E7: Robbie Williams | G7: 2003 | H7: Soundtrack | J7: dance;groovy | K7: =CONCATENATE(SUBSTITUTE(Spotify!J7,",",";"),";",J7) -> soundtrack;score;dance;groovy | M7: =Spotify!B7 -> Zimmer: A Man For All Seasons | N7: =Spotify!D7 -> Hans Zimmer;Robbie Williams | O7: =Spotify!E7 -> 37622 | P7: =ROUND(Spotify!U7,0) -> 124 | Q7: =ROUND(Spotify!L7*100,0) -> 74 | R7: =ROUND(Spotify!K7*100,0) -> 58 | S7: =Spotify!N7 -> -8.36 | T7: =ROUND(Spotify!T7*100,0) -> 82 | U7: =ROUND(Spotify!F7/60000,1) -> 4 | V7: =ROUND(Spotify!Q7*100,0) -> 1 | W7: =Spotify!G7 -> 42
A8: =RAND() -> 0.67198577 | D8: A Sky Full Of Stars | E8: Coldplay | G8: 2014 | H8: Rock | I8: Alternative | J8: alternative | K8: =CONCATENATE(SUBSTITUTE(Spotify!J8,",",";"),";",J8) -> ;alternative | M8: =Spotify!B8 -> A Sky Full of Stars | N8: =Spotify!D8 -> Coldplay | O8: =Spotify!E8 -> 41775 | P8: =ROUND(Spotify!U8,0) -> 125 | Q8: =ROUND(Spotify!L8*100,0) -> 68 | R8: =ROUND(Spotify!K8*100,0) -> 55 | S8: =Spotify!N8 -> -6.474 | T8: =ROUND(Spotify!T8*100,0) -> 16 | U8: =ROUND(Spotify!F8/60000,1) -> 4.5 | V8: =ROUND(Spotify!Q8*100,0) -> 1 | W8: =Spotify!G8 -> 88
A9: =RAND() -> 0.63150212 | C9: E | D9: A Thousand Miles | E9: Vanessa Carlton | G9: 2002 | H9: Pop | J9: dance;groovy;love;waltz | K9: =CONCATENATE(SUBSTITUTE(Spotify!J9,",",";"),";",J9) -> ;dance;groovy;love;waltz | M9: =Spotify!B9 -> A Thousand Miles | N9: =Spotify!D9 -> Vanessa Carlton | O9: =Spotify!E9 -> 37376 | P9: =ROUND(Spotify!U9,0) -> 95 | Q9: =ROUND(Spotify!L9*100,0) -> 83 | R9: =ROUND(Spotify!K9*100,0) -> 56 | S9: =Spotify!N9 -> -3.862 | T9: =ROUND(Spotify!T9*100,0) -> 27 | U9: =ROUND(Spotify!F9/60000,1) -> 4 | V9: =ROUND(Spotify!Q9*100,0) -> 32 | W9: =Spotify!G9 -> 83
A10: =RAND() -> 0.079094887 | C10: C | D10: A Thousand Years | E10: Christina Perri | G10: 2011 | H10: Soundtrack | J10: love;slow | K10: =CONCATENATE(SUBSTITUTE(Spotify!J10,",",";"),";",J10) -> soft pop;love;slow | M10: =Spotify!B10 -> a thousand years | N10: =Spotify!D10 -> Christina Perri | O10: =Spotify!E10 -> 40834 | P10: =ROUND(Spotify!U10,0) -> 139 | Q10: =ROUND(Spotify!L10*100,0) -> 41 | R10: =ROUND(Spotify!K10*100,0) -> 42 | S10: =Spotify!N10 -> -7.445 | T10: =ROUND(Spotify!T10*100,0) -> 16 | U10: =ROUND(Spotify!F10/60000,1) -> 4.8 | V10: =ROUND(Spotify!Q10*100,0) -> 31 | W10: =Spotify!G10 -> 86
A11: =RAND() -> 0.72631845 | C11: Gm | D11: Adventure Of A Lifetime | E11: Coldplay | G11: 2015 | H11: Pop | I11: Alternative | J11: dance;alternative | K11: =CONCATENATE(SUBSTITUTE(Spotify!J11,",",";"),";",J11) -> ;dance;alternative | M11: =Spotify!B11 -> Adventure of a Lifetime | N11: =Spotify!D11 -> Coldplay | O11: =Spotify!E11 -> 42342 | P11: =ROUND(Spotify!U11,0) -> 112 | Q11: =ROUND(Spotify!L11*100,0) -> 92 | R11: =ROUND(Spotify!K11*100,0) -> 64 | S11: =Spotify!N11 -> -3.887 | T11: =ROUND(Spotify!T11*100,0) -> 53 | U11: =ROUND(Spotify!F11/60000,1) -> 4.4 | V11: =ROUND(Spotify!Q11*100,0) -> 0 | W11: =Spotify!G11 -> 88
A12: =RAND() -> 0.03777012 | C12: G# | D12: Africa | E12: Toto | G12: 1982 | H12: Rock | I12: Soft Rock | J12: retro;oldies | K12: =CONCATENATE(SUBSTITUTE(Spotify!J12,",",";"),";",J12) -> yacht rock;soft rock;retro;oldies | M12: =Spotify!B12 -> Africa | N12: =Spotify!D12 -> TOTO | O12: =Spotify!E12 -> 30049 | P12: =ROUND(Spotify!U12,0) -> 93 | Q12: =ROUND(Spotify!L12*100,0) -> 37 | R12: =ROUND(Spotify!K12*100,0) -> 67 | S12: =Spotify!N12 -> -18.064 | T12: =ROUND(Spotify!T12*100,0) -> 73 | U12: =ROUND(Spotify!F12/60000,1) -> 4.9 | V12: =ROUND(Spotify!Q12*100,0) -> 26 | W12: =Spotify!G12 -> 90
A13: =RAND() -> 0.90859039 | B13: WIP | C13: E | D13: After Midnight | E13: J J Cale | G13: 1966 | H13: Rock | J13: acoustic;groovy;oldies;retro | K13: =CONCATENATE(SUBSTITUTE(Spotify!J13,",",";"),";",J13) -> blues;roots rock;blues rock;acoustic;groovy;oldies;retro | M13: =Spotify!B13 -> After Midnight | N13: =Spotify!D13 -> J.J. Cale | O13: =Spotify!E13 -> 1972 | P13: =ROUND(Spotify!U13,0) -> 96 | Q13: =ROUND(Spotify!L13*100,0) -> 31 | R13: =ROUND(Spotify!K13*100,0) -> 69 | S13: =Spotify!N13 -> -19.315 | T13: =ROUND(Spotify!T13*100,0) -> 52 | U13: =ROUND(Spotify!F13/60000,1) -> 2.4 | V13: =ROUND(Spotify!Q13*100,0) -> 17 | W13: =Spotify!G13 -> 62
B14: WIP | D14: Aicha | E14: Outlandish | G14: 2002 | H14: RnB | I14: Hip-hop | K14: =CONCATENATE(SUBSTITUTE(Spotify!J14,",",";"),";",J14) -> dansk pop; | M14: =Spotify!B14 -> Aicha | N14: =Spotify!D14 -> Outlandish | O14: =Spotify!E14 -> 37712 | P14: =ROUND(Spotify!U14,0) -> 87 | Q14: =ROUND(Spotify!L14*100,0) -> 64 | R14: =ROUND(Spotify!K14*100,0) -> 75 | S14: =Spotify!N14 -> -5.494 | T14: =ROUND(Spotify!T14*100,0) -> 61 | U14: =ROUND(Spotify!F14/60000,1) -> 4.6 | V14: =ROUND(Spotify!Q14*100,0) -> 21 | W14: =Spotify!G14 -> 58
A15: =RAND() -> 0.19557299 | D15: All About That Bass | E15: Meghan Trainor | G15: 2014 | H15: Doo-wop | J15: dance;jive;groovy | K15: =CONCATENATE(SUBSTITUTE(Spotify!J15,",",";"),";",J15) -> ;dance;jive;groovy | M15: =Spotify!B15 -> All About That Bass | N15: =Spotify!D15 -> Meghan Trainor | O15: =Spotify!E15 -> 42016 | P15: =ROUND(Spotify!U15,0) -> 134 | Q15: =ROUND(Spotify!L15*100,0) -> 89 | R15: =ROUND(Spotify!K15*100,0) -> 81 | S15: =Spotify!N15 -> -3.726 | T15: =ROUND(Spotify!T15*100,0) -> 96 | U15: =ROUND(Spotify!F15/60000,1) -> 3.2 | V15: =ROUND(Spotify!Q15*100,0) -> 6 | W15: =Spotify!G15 -> 71
A16: =RAND() -> 0.63895595 | B16: WIP | C16: C# | D16: All About You | E16: McFly | G16: 2005 | H16: Rock | I16: Pop | J16: love;pop | K16: =CONCATENATE(SUBSTITUTE(Spotify!J16,",",";"),";",J16) -> ;love;pop | M16: =Spotify!B16 -> All About You | N16: =Spotify!D16 -> McFly | O16: =Spotify!E16 -> 38353 | P16: =ROUND(Spotify!U16,0) -> 130 | Q16: =ROUND(Spotify!L16*100,0) -> 56 | R16: =ROUND(Spotify!K16*100,0) -> 54 | S16: =Spotify!N16 -> -5.313 | T16: =ROUND(Spotify!T16*100,0) -> 30 | U16: =ROUND(Spotify!F16/60000,1) -> 3.1 | V16: =ROUND(Spotify!Q16*100,0) -> 20 | W16: =Spotify!G16 -> 59
A17: =RAND() -> 0.17884601 | C17: D | D17: All I Have To Do Is Dream | E17: Everly Brothers | G17: 1958 | H17: Rock 'n' roll | J17: love;slow;oldies;retro;sweet | K17: =CONCATENATE(SUBSTITUTE(Spotify!J17,",",";"),";",J17) -> doo-wop;love;slow;oldies;retro;sweet | M17: =Spotify!B17 -> All I Have to Do Is Dream | N17: =Spotify!D17 -> The Everly Brothers | O17: =Spotify!E17 -> 23590 | P17: =ROUND(Spotify!U17,0) -> 96 | Q17: =ROUND(Spotify!L17*100,0) -> 46 | R17: =ROUND(Spotify!K17*100,0) -> 53 | S17: =Spotify!N17 -> -8.172 | T17: =ROUND(Spotify!T17*100,0) -> 53 | U17: =ROUND(Spotify!F17/60000,1) -> 2.4 | V17: =ROUND(Spotify!Q17*100,0) -> 84 | W17: =Spotify!G17 -> 70
A18: =RAND() -> 0.22293151 | C18: F | D18: All Star | E18: Smash Mouth | G18: 1999 | H18: Rock | I18: Alternative | J18: alternative | K18: =CONCATENATE(SUBSTITUTE(Spotify!J18,",",";"),";",J18) -> ;alternative | M18: =Spotify!B18 -> All Star | N18: =Spotify!D18 -> Smash Mouth | O18: =Spotify!E18 -> 36319 | P18: =ROUND(Spotify!U18,0) -> 104 | Q18: =ROUND(Spotify!L18*100,0) -> 87 | R18: =ROUND(Spotify!K18*100,0) -> 73 | S18: =Spotify!N18 -> -5.881 | T18: =ROUND(Spotify!T18*100,0) -> 78 | U18: =ROUND(Spotify!F18/60000,1) -> 3.3 | V18: =ROUND(Spotify!Q18*100,0) -> 4 | W18: =Spotify!G18 -> 82
A19: =RAND() -> 0.0021019655 | B19: WIP | C19: G | D19: Angel Of The Morning | E19: Juice Newton | G19: 1981 | H19: Country | J19: love;slow;oldies;retro | K19: =CONCATENATE(SUBSTITUTE(Spotify!J19,",",";"),";",J19) -> ;love;slow;oldies;retro | M19: =Spotify!B19 -> Angel Of The Morning | N19: =Spotify!D19 -> Juice Newton | O19: =Spotify!E19 -> 29587 | P19: =ROUND(Spotify!U19,0) -> 76 | Q19: =ROUND(Spotify!L19*100,0) -> 31 | R19: =ROUND(Spotify!K19*100,0) -> 45 | S19: =Spotify!N19 -> -9.309 | T19: =ROUND(Spotify!T19*100,0) -> 34 | U19: =ROUND(Spotify!F19/60000,1) -> 4.2 | V19: =ROUND(Spotify!Q19*100,0) -> 43 | W19: =Spotify!G19 -> 68
A20: =RAND() -> 0.50212663 | D20: Angels | E20: Robbie Williams | G20: 1997 | H20: Rock | I20: Pop / Gospel | J20: love;slow | K20: =CONCATENATE(SUBSTITUTE(Spotify!J20,",",";"),";",J20) -> ;love;slow | M20: =Spotify!B20 -> Angels | N20: =Spotify!D20 -> Robbie Williams | O20: =Spotify!E20 -> 35431 | P20: =ROUND(Spotify!U20,0) -> 150 | Q20: =ROUND(Spotify!L20*100,0) -> 59 | R20: =ROUND(Spotify!K20*100,0) -> 43 | S20: =Spotify!N20 -> -6.362 | T20: =ROUND(Spotify!T20*100,0) -> 26 | U20: =ROUND(Spotify!F20/60000,1) -> 4.4 | V20: =ROUND(Spotify!Q20*100,0) -> 16 | W20: =Spotify!G20 -> 65
A21: =RAND() -> 0.13420442 | C21: G | D21: Annie's Song | E21: John Denver | G21: 1974 | H21: Rock | I21: Folk / Country | J21: love;slow;oldies;retro;waltz | K21: =CONCATENATE(SUBSTITUTE(Spotify!J21,",",";"),";",J21) -> folk;love;slow;oldies;retro;waltz | M21: =Spotify!B21 -> Annie's Song | N21: =Spotify!D21 -> John Denver | O21: =Spotify!E21 -> 27195 | P21: =ROUND(Spotify!U21,0) -> 146 | Q21: =ROUND(Spotify!L21*100,0) -> 31 | R21: =ROUND(Spotify!K21*100,0) -> 30 | S21: =Spotify!N21 -> -10.879 | T21: =ROUND(Spotify!T21*100,0) -> 46 | U21: =ROUND(Spotify!F21/60000,1) -> 3 | V21: =ROUND(Spotify!Q21*100,0) -> 87 | W21: =Spotify!G21 -> 71
D22: Another Day In Paradise | E22: Phil Collins | G22: 1989 | H22: Rock | I22: Soft | J22: alternative;groovy | K22: =CONCATENATE(SUBSTITUTE(Spotify!J22,",",";"),";",J22) -> soft rock;alternative;groovy | M22: =Spotify!B22 -> Another Day in Paradise - 2016 Remaster | N22: =Spotify!D22 -> Phil Collins | O22: =Spotify!E22 -> 32832 | P22: =ROUND(Spotify!U22,0) -> 102 | Q22: =ROUND(Spotify!L22*100,0) -> 57 | R22: =ROUND(Spotify!K22*100,0) -> 78 | S22: =Spotify!N22 -> -7.32 | T22: =ROUND(Spotify!T22*100,0) -> 37 | U22: =ROUND(Spotify!F22/60000,1) -> 5.4 | V22: =ROUND(Spotify!Q22*100,0) -> 74 | W22: =Spotify!G22 -> 84
B23: WIP | C23: F | D23: Answer Me My Love | E23: Inger Marie | G23: 2011 | H23: Jazz | I23: Smooth | K23: =CONCATENATE(SUBSTITUTE(Spotify!J23,",",";"),";",J23) -> vocal jazz;smooth jazz;jazz pop; | M23: =Spotify!B23 -> Answer Me, My Love | N23: =Spotify!D23 -> Inger Marie Gundersen | O23: =Spotify!E23 -> 40847 | P23: =ROUND(Spotify!U23,0) -> 89 | Q23: =ROUND(Spotify!L23*100,0) -> 8 | R23: =ROUND(Spotify!K23*100,0) -> 63 | S23: =Spotify!N23 -> -27.517 | T23: =ROUND(Spotify!T23*100,0) -> 37 | U23: =ROUND(Spotify!F23/60000,1) -> 3.8 | V23: =ROUND(Spotify!Q23*100,0) -> 77 | W23: =Spotify!G23 -> 18
A24: =RAND() -> 0.69948315 | B24: WIP | C24: Cm | D24: Antonio's Song | E24: Till Brönner | F24: Michael Franks | G24: 1977 | H24: Jazz | I24: Smooth | J24: groovy;jazz;slow;oldies;retro | K24: =CONCATENATE(SUBSTITUTE(Spotify!J24,",",";"),";",J24) -> smooth jazz;jazz;groovy;jazz;slow;oldies;retro | M24: =Spotify!B24 -> Antonio's Song | N24: =Spotify!D24 -> Till Brönner | O24: =Spotify!E24 -> 38145 | P24: =ROUND(Spotify!U24,0) -> 114 | Q24: =ROUND(Spotify!L24*100,0) -> 39 | R24: =ROUND(Spotify!K24*100,0) -> 68 | S24: =Spotify!N24 -> -14.082 | T24: =ROUND(Spotify!T24*100,0) -> 65 | U24: =ROUND(Spotify!F24/60000,1) -> 5 | V24: =ROUND(Spotify!Q24*100,0) -> 46 | W24: =Spotify!G24 -> 27
A25: =RAND() -> 0.42480174 | B25: WIP | D25: Ave Maria | E25: Beyonce | G25: 2008 | H25: Pop | I25: RnB | J25: love;groovy | K25: =CONCATENATE(SUBSTITUTE(Spotify!J28,",",";"),";",J25) -> ;love;groovy | M25: =Spotify!B28 -> Believer | N25: =Spotify!D28 -> Imagine Dragons | O25: =Spotify!E28 -> 42909 | P25: =ROUND(Spotify!U28,0) -> 125 | Q25: =ROUND(Spotify!L28*100,0) -> 78 | R25: =ROUND(Spotify!K28*100,0) -> 78 | S25: =Spotify!N28 -> -4.374 | T25: =ROUND(Spotify!T28*100,0) -> 67 | U25: =ROUND(Spotify!F28/60000,1) -> 3.4 | V25: =ROUND(Spotify!Q28*100,0) -> 6 | W25: =Spotify!G28 -> 88
A26: =RAND() -> 0.26934975 | B26: WIP | C26: Bm | D26: Baby One More Time | E26: Britney Spears | G26: 1998 | H26: Pop | J26: love;groovy;dance | K26: =CONCATENATE(SUBSTITUTE(Spotify!J29,",",";"),";",J26) -> classical crossover;opera;love;groovy;dance | M26: =Spotify!B29 -> Bésame Mucho | N26: =Spotify!D29 -> Andrea Bocelli | O26: =Spotify!E29 -> 38718 | P26: =ROUND(Spotify!U29,0) -> 95 | Q26: =ROUND(Spotify!L29*100,0) -> 50 | R26: =ROUND(Spotify!K29*100,0) -> 52 | S26: =Spotify!N29 -> -8.521 | T26: =ROUND(Spotify!T29*100,0) -> 38 | U26: =ROUND(Spotify!F29/60000,1) -> 4 | V26: =ROUND(Spotify!Q29*100,0) -> 89 | W26: =Spotify!G29 -> 65
A27: =RAND() -> 0.20312101 | B27: WIP | C27: Em | D27: Beautiful Tango | E27: Hindi Zahra | G27: 2010 | H27: Soul | I27: Folk | J27: alternative;acoustic | K27: =CONCATENATE(SUBSTITUTE(Spotify!#REF!,",",";"),";",J27) -> #REF! | M27: =Spotify!#REF! -> #REF! | N27: =Spotify!#REF! -> #REF! | O27: =Spotify!#REF! -> #REF! | P27: =ROUND(Spotify!#REF!,0) -> #REF! | Q27: =ROUND(Spotify!#REF!*100,0) -> #REF! | R27: =ROUND(Spotify!#REF!*100,0) -> #REF! | S27: =Spotify!#REF! -> #REF! | T27: =ROUND(Spotify!#REF!*100,0) -> #REF! | U27: =ROUND(Spotify!#REF!/60000,1) -> #REF! | V27: =ROUND(Spotify!#REF!*100,0) -> #REF! | W27: =Spotify!#REF! -> #REF!
A28: =RAND() -> 0.21230257 | C28: Am | D28: Believer | E28: Imagine Dragons | G28: 2017 | H28: Rock | I28: Pop | J28: alternative | K28: =CONCATENATE(SUBSTITUTE(Spotify!J31,",",";"),";",J28) -> folk;folk rock;singer-songwriter;alternative | M28: =Spotify!B31 -> Big Yellow Taxi | N28: =Spotify!D31 -> Joni Mitchell | O28: =Spotify!E31 -> 43560 | P28: =ROUND(Spotify!U31,0) -> 86 | Q28: =ROUND(Spotify!L31*100,0) -> 47 | R28: =ROUND(Spotify!K31*100,0) -> 61 | S28: =Spotify!N31 -> -9.135 | T28: =ROUND(Spotify!T31*100,0) -> 97 | U28: =ROUND(Spotify!F31/60000,1) -> 2.2 | V28: =ROUND(Spotify!Q31*100,0) -> 59 | W28: =Spotify!G31 -> 46
A29: =RAND() -> 0.61707823 | C29: Am | D29: Besame Mucho | E29: Andrea Bocelli | F29: Consuelo Velazquez | G29: 1940 | H29: Latin | I29: Bolero | J29: love;slow;jazz;bossa;oldies;retro | K29: =CONCATENATE(SUBSTITUTE(Spotify!J32,",",";"),";",J29) -> ;love;slow;jazz;bossa;oldies;retro | M29: =Spotify!B32 -> Billie Jean | N29: =Spotify!D32 -> Michael Jackson | O29: =Spotify!E32 -> 39486 | P29: =ROUND(Spotify!U32,0) -> 117 | Q29: =ROUND(Spotify!L32*100,0) -> 65 | R29: =ROUND(Spotify!K32*100,0) -> 92 | S29: =Spotify!N32 -> -3.051 | T29: =ROUND(Spotify!T32*100,0) -> 85 | U29: =ROUND(Spotify!F32/60000,1) -> 4.9 | V29: =ROUND(Spotify!Q32*100,0) -> 2 | W29: =Spotify!G32 -> 82
A30: =RAND() -> 0.96996976 | B30: WIP | D30: Better When I'm Dancing | E30: Meghan Trainor | G30: 2015 | H30: Pop | J30: dance;fast | K30: =CONCATENATE(SUBSTITUTE(Spotify!J33,",",";"),";",J30) -> french jazz;dance;fast | M30: =Spotify!B33 -> Bistro Fada | N30: =Spotify!D33 -> Stephane Wrembel | O30: =Spotify!E33 -> 40676 | P30: =ROUND(Spotify!U33,0) -> 99 | Q30: =ROUND(Spotify!L33*100,0) -> 37 | R30: =ROUND(Spotify!K33*100,0) -> 76 | S30: =Spotify!N33 -> -10.908 | T30: =ROUND(Spotify!T33*100,0) -> 86 | U30: =ROUND(Spotify!F33/60000,1) -> 3 | V30: =ROUND(Spotify!Q33*100,0) -> 89 | W30: =Spotify!G33 -> 52
A31: =RAND() -> 0.039207695 | B31: WIP | D31: Big Yellow Taxi | E31: Joni Mitchell | G31: 1970 | H31: Rock | I31: Folk | J31: pop;acoustic;alternative;retro;oldies | K31: =CONCATENATE(SUBSTITUTE(Spotify!J35,",",";"),";",J31) -> ;pop;acoustic;alternative;retro;oldies | M31: =Spotify!B35 -> Black or White - Single Version | N31: =Spotify!D35 -> Michael Jackson | O31: =Spotify!E35 -> 37942 | P31: =ROUND(Spotify!U35,0) -> 115 | Q31: =ROUND(Spotify!L35*100,0) -> 93 | R31: =ROUND(Spotify!K35*100,0) -> 76 | S31: =Spotify!N35 -> -2.768 | T31: =ROUND(Spotify!T35*100,0) -> 96 | U31: =ROUND(Spotify!F35/60000,1) -> 3.3 | V31: =ROUND(Spotify!Q35*100,0) -> 11 | W31: =Spotify!G35 -> 68
D32: Billie Jean | E32: Michael Jackson | G32: 1982 | H32: Pop | K32: =CONCATENATE(SUBSTITUTE(Spotify!J36,",",";"),";",J32) -> classic rock;psychedelic rock; | M32: =Spotify!B36 -> Blackbird - Remastered 2009 | N32: =Spotify!D36 -> The Beatles | O32: =Spotify!E36 -> 25164 | P32: =ROUND(Spotify!U36,0) -> 94 | Q32: =ROUND(Spotify!L36*100,0) -> 13 | R32: =ROUND(Spotify!K36*100,0) -> 69 | S32: =Spotify!N36 -> -14.361 | T32: =ROUND(Spotify!T36*100,0) -> 37 | U32: =ROUND(Spotify!F36/60000,1) -> 2.3 | V32: =ROUND(Spotify!Q36*100,0) -> 75 | W32: =Spotify!G36 -> 80
A33: =RAND() -> 0.82305478 | B33: WIP | C33: Em | D33: Bistro Fada | E33: Stephane Wrembel | G33: 2011 | H33: Jazz | I33: Gypsy Jazz | J33: instrumental;waltz | K33: =CONCATENATE(SUBSTITUTE(Spotify!J38,",",";"),";",J33) -> folk;folk rock;instrumental;waltz | M33: =Spotify!B38 -> Blowin' in the Wind | N33: =Spotify!D38 -> Peter, Paul and Mary | O33: =Spotify!E38 -> 1963 | P33: =ROUND(Spotify!U38,0) -> 155 | Q33: =ROUND(Spotify!L38*100,0) -> 8 | R33: =ROUND(Spotify!K38*100,0) -> 38 | S33: =Spotify!N38 -> -17.77 | T33: =ROUND(Spotify!T38*100,0) -> 56 | U33: =ROUND(Spotify!F38/60000,1) -> 3 | V33: =ROUND(Spotify!Q38*100,0) -> 83 | W33: =Spotify!G38 -> 60
A34: =RAND() -> 0.83540049 | C34: C | D34: Bitter Sweet Symphony | E34: Verve | G34: 1997 | H34: Rock | I34: Alternative | J34: alternative | K34: =CONCATENATE(SUBSTITUTE(Spotify!J39,",",";"),";",J34) -> yacht rock;alternative | M34: =Spotify!B39 -> Brandy (You're a Fine Girl) | N34: =Spotify!D39 -> Looking Glass | O34: =Spotify!E39 -> 1972 | P34: =ROUND(Spotify!U39,0) -> 125 | Q34: =ROUND(Spotify!L39*100,0) -> 63 | R34: =ROUND(Spotify!K39*100,0) -> 72 | S34: =Spotify!N39 -> -11.369 | T34: =ROUND(Spotify!T39*100,0) -> 83 | U34: =ROUND(Spotify!F39/60000,1) -> 3.2 | V34: =ROUND(Spotify!Q39*100,0) -> 40 | W34: =Spotify!G39 -> 78
B35: WIP | D35: Black Or White | E35: Michael Jackson | G35: 1991 | H35: Pop | I35: RnB | K35: =CONCATENATE(SUBSTITUTE(Spotify!J40,",",";"),";",J35) -> samba;seresta;classical;chamber music;brazilian jazz;bossa nova;latin jazz;afro-cuban jazz;big band;jazz; | M35: =Spotify!B40 -> Brasileirinho | N35: =Spotify!D40 -> Waldir Azevedo;Yo-Yo Ma;Romero Lubambo;Cyro Baptista;Jose De Faria;José Da Silva;Helio Alves;Nilson Matta;Paquito D'Rivera | O35: =Spotify!E40 -> 2003 | P35: =ROUND(Spotify!U40,0) -> 105 | Q35: =ROUND(Spotify!L40*100,0) -> 52 | R35: =ROUND(Spotify!K40*100,0) -> 49 | S35: =Spotify!N40 -> -13.08 | T35: =ROUND(Spotify!T40*100,0) -> 92 | U35: =ROUND(Spotify!F40/60000,1) -> 3.4 | V35: =ROUND(Spotify!Q40*100,0) -> 35 | W35: =Spotify!G40 -> 33
A36: =RAND() -> 0.12828128 | B36: WIP | C36: G | D36: Blackbird | E36: Beatles | G36: 1968 | H36: Folk | J36: oldies;retro;acoustic;alternative;folk | K36: =CONCATENATE(SUBSTITUTE(Spotify!J41,",",";"),";",J36) -> ;oldies;retro;acoustic;alternative;folk | M36: =Spotify!B41 -> Breakfast At Tiffany's | N36: =Spotify!D41 -> Deep Blue Something | O36: =Spotify!E41 -> 34700 | P36: =ROUND(Spotify!U41,0) -> 110 | Q36: =ROUND(Spotify!L41*100,0) -> 83 | R36: =ROUND(Spotify!K41*100,0) -> 62 | S36: =Spotify!N41 -> -5.548 | T36: =ROUND(Spotify!T41*100,0) -> 54 | U36: =ROUND(Spotify!F41/60000,1) -> 4.3 | V36: =ROUND(Spotify!Q41*100,0) -> 11 | W36: =Spotify!G41 -> 73
A37: =RAND() -> 0.32569321 | C37: Cm | D37: Blinding Lights | E37: Weeknd | G37: 2019 | H37: RnB | I37: Soul | J37: groovy;dance;fast;love | K37: =CONCATENATE(SUBSTITUTE(Spotify!J42,",",";"),";",J37) -> ;groovy;dance;fast;love | M37: =Spotify!B42 -> Breathe (2 AM) | N37: =Spotify!D42 -> Anna Nalick | O37: =Spotify!E42 -> 2005 | P37: =ROUND(Spotify!U42,0) -> 170 | Q37: =ROUND(Spotify!L42*100,0) -> 45 | R37: =ROUND(Spotify!K42*100,0) -> 39 | S37: =Spotify!N42 -> -7.715 | T37: =ROUND(Spotify!T42*100,0) -> 29 | U37: =ROUND(Spotify!F42/60000,1) -> 4.7 | V37: =ROUND(Spotify!Q42*100,0) -> 42 | W37: =Spotify!G42 -> 66
A38: =RAND() -> 0.67179284 | C38: D | D38: Blowin' In The Wind | E38: Peter Paul and Mary | F38: Bob Dylan | G38: 1962 | H38: Folk | J38: acoustic;oldies;retro;folk | K38: =CONCATENATE(SUBSTITUTE(Spotify!J43,",",";"),";",J38) -> ;acoustic;oldies;retro;folk | M38: =Spotify!B43 -> Brown Eyed Girl | N38: =Spotify!D43 -> Van Morrison | O38: =Spotify!E43 -> 1967-09 | P38: =ROUND(Spotify!U43,0) -> 151 | Q38: =ROUND(Spotify!L43*100,0) -> 58 | R38: =ROUND(Spotify!K43*100,0) -> 49 | S38: =Spotify!N43 -> -10.964 | T38: =ROUND(Spotify!T43*100,0) -> 91 | U38: =ROUND(Spotify!F43/60000,1) -> 3.1 | V38: =ROUND(Spotify!Q43*100,0) -> 19 | W38: =Spotify!G43 -> 19
A39: =RAND() -> 0.19987132 | C39: E | D39: Brandy | E39: Looking Glass | G39: 1972 | H39: Rock | I39: Soft | J39: groovy;dance;fast;oldies;retro | K39: =CONCATENATE(SUBSTITUTE(Spotify!J44,",",";"),";",J39) -> ;groovy;dance;fast;oldies;retro | M39: =Spotify!B44 -> Budapest | N39: =Spotify!D44 -> George Ezra | O39: =Spotify!E44 -> 41820 | P39: =ROUND(Spotify!U44,0) -> 128 | Q39: =ROUND(Spotify!L44*100,0) -> 46 | R39: =ROUND(Spotify!K44*100,0) -> 72 | S39: =Spotify!N44 -> -8.303 | T39: =ROUND(Spotify!T44*100,0) -> 39 | U39: =ROUND(Spotify!F44/60000,1) -> 3.3 | V39: =ROUND(Spotify!Q44*100,0) -> 8 | W39: =Spotify!G44 -> 83
A40: =RAND() -> 0.53505531 | B40: WIP | C40: A | D40: Brasileirinho | E40: Waldir Azavedo | G40: 1947 | H40: Choro | J40: instrumental | K40: =CONCATENATE(SUBSTITUTE(Spotify!J45,",",";"),";",J40) -> soft pop;acoustic pop;instrumental | M40: =Spotify!B45 -> Butterfly | N40: =Spotify!D45 -> Jason Mraz | O40: =Spotify!E45 -> 39580 | P40: =ROUND(Spotify!U45,0) -> 108 | Q40: =ROUND(Spotify!L45*100,0) -> 66 | R40: =ROUND(Spotify!K45*100,0) -> 72 | S40: =Spotify!N45 -> -7.207 | T40: =ROUND(Spotify!T45*100,0) -> 80 | U40: =ROUND(Spotify!F45/60000,1) -> 5 | V40: =ROUND(Spotify!Q45*100,0) -> 15 | W40: =Spotify!G45 -> 46
A41: =RAND() -> 0.34474758 | B41: WIP | C41: D | D41: Breakfast At Tiffany's | E41: Deep Blue Something | G41: 1995 | H41: Rock | I41: Alternative | J41: love | K41: =CONCATENATE(SUBSTITUTE(Spotify!J46,",",";"),";",J41) -> doo-wop;love | M41: =Spotify!B46 -> Bye Bye Love | N41: =Spotify!D46 -> The Everly Brothers | O41: =Spotify!E46 -> 23590 | P41: =ROUND(Spotify!U46,0) -> 170 | Q41: =ROUND(Spotify!L46*100,0) -> 52 | R41: =ROUND(Spotify!K46*100,0) -> 55 | S41: =Spotify!N46 -> -9.176 | T41: =ROUND(Spotify!T46*100,0) -> 89 | U41: =ROUND(Spotify!F46/60000,1) -> 2.4 | V41: =ROUND(Spotify!Q46*100,0) -> 72 | W41: =Spotify!G46 -> 54
...

Sheet Classical
A1: Title | C1: Work number | D1: Composer | E1: Length
A3: Minuet in G - Gm | C3: 114-115 | D3: Bach, J. S. (Petzold) | E3: 0.0024305556
A4: Minuet in G | C4: 116 | D4: Bach, J. S. | E4: 0.0013888889
A5: Jesu Joy of Man’s Desiring | B5: ♪♪ | C5: 147 | D5: Bach, J. S. | E5: 0.0024305556
A6: Arioso | B6: ♪♪ | C6: 156 | D6: Bach, J. S. | E6: 0.0017361111
A7: Prelude in C No 1 | C7: 553 | D7: Bach, J. S. | E7: 0.0020833333
A8: Invention 01 | C8: 772 | D8: Bach, J. S. | E8: 0.00069444444
A9: Invention 04 | C9: 775 | D9: Bach, J. S. | E9: 0.00069444444
A10: Invention 10 | C10: 781 | D10: Bach, J. S. | E10: 0.00081018519
A11: Prelude for Piano No. 1 | C11: 846 | D11: Bach, J. S. | E11: 0.0015625
A12: Prelude for Piano No. 3 | C12: 848 | D12: Bach, J. S. | E12: 0.0013888889
A13: Prelude for Piano No. 5 | C13: 850 | D13: Bach, J. S. | E13: 0.0010416667
A14: Goldberg Variations, Var. 1 | B14: ♪♪ | C14: 988 | D14: Bach, J. S. | E14: 0.0015625
A15: Goldberg Variations, Var. 5 | C15: 988 | D15: Bach, J. S. | E15: 0.0013888889
A16: Violin Partita 2 Mvt 4 - Gigue | B16: ♪♪ | C16: 1004 | D16: Bach, J. S. | E16: 0.0017361111 | F16: no repeats
A17: Orchestral Suite 3 - Air | C17: 1068 | D17: Bach, J. S. | E17: 0.003125
A18: Piano Sonata 8 Mvt 2 - Adagio Cantabile | C18: 13 | D18: Beethoven, L. v. | E18: 0.0034722222
A19: Bolero | B19: ♪♪ | D19: Calace, Rafael | E19: 0.0020833333
A20: Allemande | C20: 437 | D20: Handel, G. F. | E20: 0.0015046296
A21: Piano Sonata 16 “Facile” | C21: 545 | D21: Mozart, W. A. | E21: 0.0069444444
A22: Carnival of the Animals – The Swan | D22: Saint-Saens, Camille | E22: 0.0017361111
A23: Gymnopedie for Piano No 1 | B23: ♪♪ | D23: Satie, Erik | E23: 0.0018518519
A24: Estudio No 6 | B24: ♪♪ | D24: Sor, Fernando | E24: 0.0015046296
A25: Cavatina | B25: ♪♪ | D25: Stanley Myers | E25: 0.0027777778
A26: Recuerdos de la Alhambra | B26: ♪♪ | D26: Tarrega, Francisco | E26: 0.0034722222
A27: Bistro Fada | B27: ♪♪ | D27: Wrembel, Stephane | E27: 0.0020833333
A28: Tico Tico No Fubá | D28: Zequinha de Abreu | E28: 0.0017361111
A29: Cantabile | B29: ♪♪ | E29: 0.002662037
A38: SOLO
A39: Violin Partita 1 Mvt 3 - Double | C39: 1002 | D39: Bach, J. S. | E39: 0.0019097222
A40: Violin Partita 2 Mvt 4 - Gigue | B40: ♪♪ | C40: 1004 | D40: Bach, J. S. | E40: 0.0017361111 | F40: no repeats
A41: Violin Partita 3 Mvt 6 - Gigue | C41: 1006 | D41: Bach, J. S. | E41: 0.0013888889
A42: Cello Suite No. 1 Mvt. 3 | C42: 1007 | D42: Bach, J. S. | E42: 0.0019097222
A43: Cello Suite No. 3 Mvt. 3 | C43: 1009 | D43: Bach, J. S. | E43: 0.0024305556

Sheet Duo
A1: # | B1: WIP | C1: Key | D1: Title | E1: Artist | F1: Cover? | G1: Year | H1: Genre | I1: Genre 2 | J1: BPM | K1: Listen
A3: =RAND() -> 0.14837152 | C3: F#m | D3: 1973 | E3: James Blunt | G3: 2007 | H3: Rock | I3: Pop | J3: 135 | K3: 1973
A4: =RAND() -> 0.67025593 | C4: F | D4: A Little More | E4: Eric Hutchinson | G4: 2014 | H4: Rock | I4: Pop | J4: 160 | K4: A Little More
A5: =RAND() -> 0.36790162 | B5: WIP | C5: Dm | D5: A Man For All Seasons | E5: Robbie Williams | G5: 2003 | H5: Soundtrack | J5: 130 | K5: A Man For All Seasons
A6: =RAND() -> 0.70158295 | C6: Gm | D6: Adventure Of A Lifetime | E6: Coldplay | G6: 2015 | H6: Pop | I6: Alternative | J6: 115 | K6: Adventure Of A Lifetime
A7: =RAND() -> 0.37373296 | B7: WIP | C7: G# | D7: Africa | E7: Toto | G7: 2002 | H7: Rock | I7: Soft Rock | J7: 90 | K7: Africa
A8: =RAND() -> 0.21364367 | D8: After Midnight | E8: J J Cale | G8: 1966 | H8: Rock | J8: 95 | K8: After Midnight
A9: =RAND() -> 0.41549909 | C9: C# | D9: All About You | E9: McFly | G9: 2005 | H9: Rock | I9: Pop | J9: 140 | K9: All About You
A10: =RAND() -> 0.41023602 | C10: D | D10: All I Have To Do Is Dream | E10: Everly Brothers | G10: 1958 | H10: Rock 'n' roll | J10: 110 | K10: All I Have To Do Is Dream
A11: =RAND() -> 0.12518281 | C11: F | D11: All Star | E11: Smash Mouth | G11: 1999 | H11: Rock | I11: Alternative | J11: 120 | K11: All Star
A12: =RAND() -> 0.78891691 | C12: G | D12: Angel Of The Morning | E12: Juice Newton | G12: 1981 | H12: Country | J12: 85 | K12: Angel Of The Morning
A13: =RAND() -> 0.82450178 | D13: Angels | E13: Robbie Williams | G13: 1997 | H13: Rock | I13: Pop / Gospel | J13: 85 | K13: Angels
A14: =RAND() -> 0.43959258 | C14: G | D14: Annie's Song | E14: John Denver | G14: 1974 | H14: Rock | I14: Folk / Country | J14: 60 | K14: Annie's Song
A15: =RAND() -> 0.80834218 | C15: Cm | D15: Antonio's Song | E15: Michael Franks | F15: Til Broenner | G15: 1977 | H15: Jazz | I15: Smooth | J15: 100 | K15: Antonio's Song
A16: =RAND() -> 0.74316684 | C16: G# | D16: April Come She Will | E16: Simon and Garfunkel | G16: 1966 | H16: Rock | I16: Folk | J16: 100 | K16: April Come She Will
A17: =RAND() -> 0.98779878 | C17: Em | D17: Bistro Fada | E17: Stephane Wrembel | G17: 2011 | H17: Soundtrack | I17: Gypsy Jazz | J17: 160 | K17: Bistro Fada
A18: =RAND() -> 0.92569413 | C18: G | D18: Blackbird | E18: Beatles | G18: 1968 | H18: Folk | J18: 100 | K18: Blackbird
A19: =RAND() -> 0.23174325 | D19: Blinding Lights | E19: Weeknd | G19: 2019 | H19: RnB | I19: Soul | J19: 160 | K19: Blinding Lights
A20: =RAND() -> 0.46256639 | C20: D | D20: Blowin' In The Wind | E20: Peter Paul and Mary | F20: Bob Dylan | G20: 1962 | H20: Folk | J20: 80 | K20: Blowin' In The Wind
A21: =RAND() -> 0.47303474 | B21: WIP | C21: F | D21: Brandy | E21: Looking Glass | G21: 1972 | H21: Rock | I21: Soft | J21: 140 | K21: Brandy
A22: =RAND() -> 0.37361949 | B22: WIP | C22: A | D22: Brasileirinho | E22: Waldir Azavedo | G22: 1947 | H22: Choro | J22: 110 | K22: Brasileirinho
A23: =RAND() -> 0.78475559 | B23: WIP | C23: D | D23: Breakfast At Tiffany's | E23: Deep Blue Something | G23: 1995 | H23: Rock | I23: Alternative | J23: 115 | K23: Breakfast At Tiffany's
A24: =RAND() -> 0.0024338179 | C24: G | D24: Brown Eyed Girl | E24: Van Morrison | G24: 1967 | H24: Rock | J24: 150 | K24: Brown Eyed Girl
A25: =RAND() -> 0.90966384 | C25: F | D25: Budapest | E25: George Ezra | G25: 2013 | H25: Rock | I25: Folk | J25: 120 | K25: Budapest
A26: =RAND() -> 0.44947692 | C26: Fm | D26: Butterfly | E26: Jason Mraz | G26: 2008 | H26: Pop | J26: 120 | K26: Butterfly
A27: =RAND() -> 0.95274883 | C27: G | D27: Bye Bye Love | E27: Everly Brothers | G27: 1957 | H27: Country | I27: Rock | J27: 170 | K27: Bye Bye Love
A28: =RAND() -> 0.28659819 | B28: WIP | D28: Calendar Girl | E28: Neil Sedaka | G28: 1959 | H28: Pop | J28: 140 | K28: Calendar Girl
A29: =RAND() -> 0.52360261 | C29: Am | D29: Californication | E29: Red Hot Chili Peppers | G29: 1999 | H29: Alternative | J29: 90 | K29: Californication
A30: =RAND() -> 0.76350061 | C30: D | D30: Can't Help Falling In Love | E30: Elvis Presley | G30: 1961 | H30: Rock | I30: Soft Rock | J30: 40 | K30: Can't Help Falling In Love
A31: =RAND() -> 0.71882195 | C31: Dm | D31: Careless Whisper | E31: George Michael | G31: 1984 | H31: Pop | J31: 90 | K31: Careless Whisper
A32: =RAND() -> 0.023050649 | C32: C | D32: Carry You Home | E32: James Blunt | G32: 2008 | H32: Rock | I32: Folk | J32: 95 | K32: Carry You Home
A33: =RAND() -> 0.89729297 | B33: WIP | C33: A | D33: Catch and Release | E33: Matt Simons | G33: 2007 | H33: Pop | J33: 85 | K33: Catch and Release
A34: =RAND() -> 0.64450656 | B34: WIP | C34: Am | D34: Chained To The Rhythm | E34: Katy Perry | G34: 2017 | H34: Disco | J34: 100 | K34: Chained To The Rhythm
A35: =RAND() -> 0.83584534 | C35: G | D35: Clocks | E35: Coldplay | G35: 2002 | H35: Rock | I35: Alternative | J35: 130 | K35: Clocks
A36: =RAND() -> 0.060624896 | C36: F | D36: Closing Time | E36: Semisonic | G36: 1998 | H36: Rock | J36: 100 | K36: Closing Time
A37: =RAND() -> 0.36658231 | D37: Cloud Number Nine | E37: Bryan Adams | G37: 1999 | H37: Pop | J37: 120 | K37: Cloud Number Nine
A38: =RAND() -> 0.51157962 | B38: WIP | D38: Come Away With Me | E38: Norah Jones | G38: 2002 | H38: Pop | I38: Jazz | K38: Come Away With Me
A39: =RAND() -> 0.38444713 | D39: Count On Me | E39: Bruno Mars | G39: 2010 | H39: Pop | J39: 110 | K39: Count On Me
A40: =RAND() -> 0.76468641 | D40: Country Roads | E40: John Denver | G40: 1971 | H40: Country | J40: 100 | K40: Country Roads
A41: =RAND() -> 0.98522209 | C41: Cm | D41: Crazy | E41: Gnarles Barkley | G41: 2006 | H41: Soul | J41: 110 | K41: Crazy
...

Sheet CSV
A1: =IF((Contemporary!D1<>""),(CONCATENATE(Contemporary!D1,",",Contemporary!E1,",",Contemporary!G1,",",Contemporary!H1,",",Contemporary!P1,",",Contemporary!Q1,",",Contemporary!R1,",",Contemporary!T1,",",Contemporary!W1,",",Contemporary!B1,",",SUBSTITUTE(B1,",","%2c"),",",IF(Contemporary!K1<>"",Contemporary!K1,CONCATENATE(Contemporary!H1,";",Contemporary!I1)),",",Spotify!A1)),"") -> Title,Artist,Year,Genre,BPM,Energy,Dance,Valence,Popularity,WIP,,Tags,Spotify ID
A2: =IF((Contemporary!D2<>""),(CONCATENATE(Contemporary!D2,",",Contemporary!E2,",",Contemporary!G2,",",Contemporary!H2,",",Contemporary!P2,",",Contemporary!Q2,",",Contemporary!R2,",",Contemporary!T2,",",Contemporary!W2,",",Contemporary!B2,",",SUBSTITUTE(B2,",","%2c"),",",IF(Contemporary!K2<>"",Contemporary!K2,CONCATENATE(Contemporary!H2,";",Contemporary!I2)),",",Spotify!A2)),"")
A3: =IF((Contemporary!D3<>""),(CONCATENATE(Contemporary!D3,",",Contemporary!E3,",",Contemporary!G3,",",Contemporary!H3,",",Contemporary!P3,",",Contemporary!Q3,",",Contemporary!R3,",",Contemporary!T3,",",Contemporary!W3,",",Contemporary!B3,",",SUBSTITUTE(B3,",","%2c"),",",IF(Contemporary!K3<>"",Contemporary!K3,CONCATENATE(Contemporary!H3,";",Contemporary!I3)),",",Spotify!A3)),"") -> 1973,James Blunt,2007,Rock,123,67,72,77,75,WIP,,;pop;alternative;love;dance,1BV0m40U0M4t1SLIsDnwZl
A4: =IF((Contemporary!D4<>""),(CONCATENATE(Contemporary!D4,",",Contemporary!E4,",",Contemporary!G4,",",Contemporary!H4,",",Contemporary!P4,",",Contemporary!Q4,",",Contemporary!R4,",",Contemporary!T4,",",Contemporary!W4,",",Contemporary!B4,",",SUBSTITUTE(B4,",","%2c"),",",IF(Contemporary!K4<>"",Contemporary!K4,CONCATENATE(Contemporary!H4,";",Contemporary!I4)),",",Spotify!A4)),"") -> A Hard Day's Night,Beatles,1964,Rock,139,82,55,76,54,,,classic rock;psychedelic rock;dance;jive;fast;groovy;love;oldies;retro,1pctwlBtIcKIjQMzsVcGHB
A5: =IF((Contemporary!D5<>""),(CONCATENATE(Contemporary!D5,",",Contemporary!E5,",",Contemporary!G5,",",Contemporary!H5,",",Contemporary!P5,",",Contemporary!Q5,",",Contemporary!R5,",",Contemporary!T5,",",Contemporary!W5,",",Contemporary!B5,",",SUBSTITUTE(B5,",","%2c"),",",IF(Contemporary!K5<>"",Contemporary!K5,CONCATENATE(Contemporary!H5,";",Contemporary!I5)),",",Spotify!A5)),"") -> A Little Less Conversation,Elvis Presley,1968,Rock,114,80,58,84,56,WIP,,rockabilly;rock and roll;dance;jive;fast;groovy;love;oldies;retro,47y8hRlWLEJ4VafE6LMjEZ
A6: =IF((Contemporary!D6<>""),(CONCATENATE(Contemporary!D6,",",Contemporary!E6,",",Contemporary!G6,",",Contemporary!H6,",",Contemporary!P6,",",Contemporary!Q6,",",Contemporary!R6,",",Contemporary!T6,",",Contemporary!W6,",",Contemporary!B6,",",SUBSTITUTE(B6,",","%2c"),",",IF(Contemporary!K6<>"",Contemporary!K6,CONCATENATE(Contemporary!H6,";",Contemporary!I6)),",",Spotify!A6)),"") -> A Little More,Eric Hutchinson,2014,Rock,80,74,64,94,44,WIP,,;fast;dance;groovy;alternative,3AH12fVi34vJVqriMpM6Bo
A7: =IF((Contemporary!D7<>""),(CONCATENATE(Contemporary!D7,",",Contemporary!E7,",",Contemporary!G7,",",Contemporary!H7,",",Contemporary!P7,",",Contemporary!Q7,",",Contemporary!R7,",",Contemporary!T7,",",Contemporary!W7,",",Contemporary!B7,",",SUBSTITUTE(B7,",","%2c"),",",IF(Contemporary!K7<>"",Contemporary!K7,CONCATENATE(Contemporary!H7,";",Contemporary!I7)),",",Spotify!A7)),"") -> A Man For All Seasons,Robbie Williams,2003,Soundtrack,124,74,58,82,42,WIP,,soundtrack;score;dance;groovy,3RIm56NRLSZYo1xgHlbPH4
A8: =IF((Contemporary!D8<>""),(CONCATENATE(Contemporary!D8,",",Contemporary!E8,",",Contemporary!G8,",",Contemporary!H8,",",Contemporary!P8,",",Contemporary!Q8,",",Contemporary!R8,",",Contemporary!T8,",",Contemporary!W8,",",Contemporary!B8,",",SUBSTITUTE(B8,",","%2c"),",",IF(Contemporary!K8<>"",Contemporary!K8,CONCATENATE(Contemporary!H8,";",Contemporary!I8)),",",Spotify!A8)),"") -> A Sky Full Of Stars,Coldplay,2014,Rock,125,68,55,16,88,,,;alternative,0FDzzruyVECATHXKHFs9eJ
A9: =IF((Contemporary!D9<>""),(CONCATENATE(Contemporary!D9,",",Contemporary!E9,",",Contemporary!G9,",",Contemporary!H9,",",Contemporary!P9,",",Contemporary!Q9,",",Contemporary!R9,",",Contemporary!T9,",",Contemporary!W9,",",Contemporary!B9,",",SUBSTITUTE(B9,",","%2c"),",",IF(Contemporary!K9<>"",Contemporary!K9,CONCATENATE(Contemporary!H9,";",Contemporary!I9)),",",Spotify!A9)),"") -> A Thousand Miles,Vanessa Carlton,2002,Pop,95,83,56,27,83,,,;dance;groovy;love;waltz,4w1lzcaoZ1IC2K5TwjalRP
A10: =IF((Contemporary!D10<>""),(CONCATENATE(Contemporary!D10,",",Contemporary!E10,",",Contemporary!G10,",",Contemporary!H10,",",Contemporary!P10,",",Contemporary!Q10,",",Contemporary!R10,",",Contemporary!T10,",",Contemporary!W10,",",Contemporary!B10,",",SUBSTITUTE(B10,",","%2c"),",",IF(Contemporary!K10<>"",Contemporary!K10,CONCATENATE(Contemporary!H10,";",Contemporary!I10)),",",Spotify!A10)),"") -> A Thousand Years,Christina Perri,2011,Soundtrack,139,41,42,16,86,,,soft pop;love;slow,6lanRgr6wXibZr8KgzXxBl
A11: =IF((Contemporary!D11<>""),(CONCATENATE(Contemporary!D11,",",Contemporary!E11,",",Contemporary!G11,",",Contemporary!H11,",",Contemporary!P11,",",Contemporary!Q11,",",Contemporary!R11,",",Contemporary!T11,",",Contemporary!W11,",",Contemporary!B11,",",SUBSTITUTE(B11,",","%2c"),",",IF(Contemporary!K11<>"",Contemporary!K11,CONCATENATE(Contemporary!H11,";",Contemporary!I11)),",",Spotify!A11)),"") -> Adventure Of A Lifetime,Coldplay,2015,Pop,112,92,64,53,88,,,;dance;alternative,69uxyAqqPIsUyTO8txoP2M
A12: =IF((Contemporary!D12<>""),(CONCATENATE(Contemporary!D12,",",Contemporary!E12,",",Contemporary!G12,",",Contemporary!H12,",",Contemporary!P12,",",Contemporary!Q12,",",Contemporary!R12,",",Contemporary!T12,",",Contemporary!W12,",",Contemporary!B12,",",SUBSTITUTE(B12,",","%2c"),",",IF(Contemporary!K12<>"",Contemporary!K12,CONCATENATE(Contemporary!H12,";",Contemporary!I12)),",",Spotify!A12)),"") -> Africa,Toto,1982,Rock,93,37,67,73,90,,,yacht rock;soft rock;retro;oldies,2374M0fQpWi3dLnB54qaLX
... A24: =IF((Contemporary!D24<>""),(CONCATENATE(Contemporary!D24,",",Contemporary!E24,",",Contemporary!G24,",",Contemporary!H24,",",Contemporary!P24,",",Contemporary!Q24,",",Contemporary!R24,",",Contemporary!T24,",",Contemporary!W24,",",Contemporary!B24,",",SUBSTITUTE(B24,",","%2c"),",",IF(Contemporary!K24<>"",Contemporary!K24,CONCATENATE(Contemporary!H24,";",Contemporary!I24)),",",Spotify!A24)),"") -> Antonio's Song,Till Brönner,1977,Jazz,114,39,68,65,27,WIP,,smooth jazz;jazz;groovy;jazz;slow;oldies;retro,51FAWuc1iPdM06S65Plx11
A25: =IF((Contemporary!#REF!<>""),(CONCATENATE(Contemporary!#REF!,",",Contemporary!#REF!,",",Contemporary!#REF!,",",Contemporary!#REF!,",",Contemporary!#REF!,",",Contemporary!#REF!,",",Contemporary!#REF!,",",Contemporary!#REF!,",",Contemporary!#REF!,",",Contemporary!#REF!,",",SUBSTITUTE(B25,",","%2c"),",",IF(Contemporary!#REF!<>"",Contemporary!#REF!,CONCATENATE(Contemporary!#REF!,";",Contemporary!#REF!)),",",Spotify!#REF!)),"") -> #REF!
A26: =IF((Contemporary!#REF!<>""),(CONCATENATE(Contemporary!#REF!,",",Contemporary!#REF!,",",Contemporary!#REF!,",",Contemporary!#REF!,",",Contemporary!#REF!,",",Contemporary!#REF!,",",Contemporary!#REF!,",",Contemporary!#REF!,",",Contemporary!#REF!,",",Contemporary!#REF!,",",SUBSTITUTE(B26,",","%2c"),",",IF(Contemporary!#REF!<>"",Contemporary!#REF!,CONCATENATE(Contemporary!#REF!,";",Contemporary!#REF!)),",",Spotify!A25)),"") -> #REF!
A27: =IF((Contemporary!#REF!<>""),(CONCATENATE(Contemporary!#REF!,",",Contemporary!#REF!,",",Contemporary!#REF!,",",Contemporary!#REF!,",",Contemporary!#REF!,",",Contemporary!#REF!,",",Contemporary!#REF!,",",Contemporary!#REF!,",",Contemporary!#REF!,",",Contemporary!#REF!,",",SUBSTITUTE(B27,",","%2c"),",",IF(Contemporary!#REF!<>"",Contemporary!#REF!,CONCATENATE(Contemporary!#REF!,";",Contemporary!#REF!)),",",Spotify!A26)),"") -> #REF!
A28: =IF((Contemporary!#REF!<>""),(CONCATENATE(Contemporary!#REF!,",",Contemporary!#REF!,",",Contemporary!#REF!,",",Contemporary!#REF!,",",Contemporary!#REF!,",",Contemporary!#REF!,",",Contemporary!#REF!,",",Contemporary!#REF!,",",Contemporary!#REF!,",",Contemporary!#REF!,",",SUBSTITUTE(B28,",","%2c"),",",IF(Contemporary!#REF!<>"",Contemporary!#REF!,CONCATENATE(Contemporary!#REF!,";",Contemporary!#REF!)),",",Spotify!A27)),"") -> #REF!
A29: =IF((Contemporary!D25<>""),(CONCATENATE(Contemporary!D25,",",Contemporary!E25,",",Contemporary!G25,",",Contemporary!H25,",",Contemporary!P25,",",Contemporary!Q25,",",Contemporary!R25,",",Contemporary!T25,",",Contemporary!W25,",",Contemporary!B25,",",SUBSTITUTE(B29,",","%2c"),",",IF(Contemporary!K25<>"",Contemporary!K25,CONCATENATE(Contemporary!H25,";",Contemporary!I25)),",",Spotify!A28)),"") -> Ave Maria,Beyonce,2008,Pop,125,78,78,67,88,WIP,,;love;groovy,0pqnGHJpmpxLKifKRmU6WP
A30: =IF((Contemporary!D26<>""),(CONCATENATE(Contemporary!D26,",",Contemporary!E26,",",Contemporary!G26,",",Contemporary!H26,",",Contemporary!P26,",",Contemporary!Q26,",",Contemporary!R26,",",Contemporary!T26,",",Contemporary!W26,",",Contemporary!B26,",",SUBSTITUTE(B30,",","%2c"),",",IF(Contemporary!K26<>"",Contemporary!K26,CONCATENATE(Contemporary!H26,";",Contemporary!I26)),",",Spotify!A29)),"") -> Baby One More Time,Britney Spears,1998,Pop,95,50,52,38,65,WIP,,classical crossover;opera;love;groovy;dance,5WHnE8MsLFHqSUwecrs7WO
A31: =IF((Contemporary!#REF!<>""),(CONCATENATE(Contemporary!#REF!,",",Contemporary!#REF!,",",Contemporary!#REF!,",",Contemporary!#REF!,",",Contemporary!#REF!,",",Contemporary!#REF!,",",Contemporary!#REF!,",",Contemporary!#REF!,",",Contemporary!#REF!,",",Contemporary!#REF!,",",SUBSTITUTE(B31,",","%2c"),",",IF(Contemporary!#REF!<>"",Contemporary!#REF!,CONCATENATE(Contemporary!#REF!,";",Contemporary!#REF!)),",",Spotify!A30)),"") -> #REF!
A32: =IF((Contemporary!D27<>""),(CONCATENATE(Contemporary!D27,",",Contemporary!E27,",",Contemporary!G27,",",Contemporary!H27,",",Contemporary!P27,",",Contemporary!Q27,",",Contemporary!R27,",",Contemporary!T27,",",Contemporary!W27,",",Contemporary!B27,",",SUBSTITUTE(B32,",","%2c"),",",IF(Contemporary!K27<>"",Contemporary!K27,CONCATENATE(Contemporary!H27,";",Contemporary!I27)),",",Spotify!#REF!)),"") -> #REF!
A33: =IF((Contemporary!D28<>""),(CONCATENATE(Contemporary!D28,",",Contemporary!E28,",",Contemporary!G28,",",Contemporary!H28,",",Contemporary!P28,",",Contemporary!Q28,",",Contemporary!R28,",",Contemporary!T28,",",Contemporary!W28,",",Contemporary!B28,",",SUBSTITUTE(B33,",","%2c"),",",IF(Contemporary!K28<>"",Contemporary!K28,CONCATENATE(Contemporary!H28,";",Contemporary!I28)),",",Spotify!A31)),"") -> Believer,Imagine Dragons,2017,Rock,86,47,61,97,46,,,folk;folk rock;singer-songwriter;alternative,1wfzOH54LylpiG8hAOjKcS
A34: =IF((Contemporary!D29<>""),(CONCATENATE(Contemporary!D29,",",Contemporary!E29,",",Contemporary!G29,",",Contemporary!H29,",",Contemporary!P29,",",Contemporary!Q29,",",Contemporary!R29,",",Contemporary!T29,",",Contemporary!W29,",",Contemporary!B29,",",SUBSTITUTE(B34,",","%2c"),",",IF(Contemporary!K29<>"",Contemporary!K29,CONCATENATE(Contemporary!H29,";",Contemporary!I29)),",",Spotify!A32)),"") -> Besame Mucho,Andrea Bocelli,1940,Latin,117,65,92,85,82,,,;love;slow;jazz;bossa;oldies;retro,5ChkMS8OtdzJeqyybCc9R5
A35: =IF((Contemporary!D30<>""),(CONCATENATE(Contemporary!D30,",",Contemporary!E30,",",Contemporary!G30,",",Contemporary!H30,",",Contemporary!P30,",",Contemporary!Q30,",",Contemporary!R30,",",Contemporary!T30,",",Contemporary!W30,",",Contemporary!B30,",",SUBSTITUTE(B35,",","%2c"),",",IF(Contemporary!K30<>"",Contemporary!K30,CONCATENATE(Contemporary!H30,";",Contemporary!I30)),",",Spotify!A33)),"") -> Better When I'm Dancing,Meghan Trainor,2015,Pop,99,37,76,86,52,WIP,,french jazz;dance;fast,08T5wMbEnPN8ghT8o24KY6
A36: =IF((Contemporary!#REF!<>""),(CONCATENATE(Contemporary!#REF!,",",Contemporary!#REF!,",",Contemporary!#REF!,",",Contemporary!#REF!,",",Contemporary!#REF!,",",Contemporary!#REF!,",",Contemporary!#REF!,",",Contemporary!#REF!,",",Contemporary!#REF!,",",Contemporary!#REF!,",",SUBSTITUTE(B36,",","%2c"),",",IF(Contemporary!#REF!<>"",Contemporary!#REF!,CONCATENATE(Contemporary!#REF!,";",Contemporary!#REF!)),",",Spotify!A34)),"") -> #REF!
A37: =IF((Contemporary!D31<>""),(CONCATENATE(Contemporary!D31,",",Contemporary!E31,",",Contemporary!G31,",",Contemporary!H31,",",Contemporary!P31,",",Contemporary!Q31,",",Contemporary!R31,",",Contemporary!T31,",",Contemporary!W31,",",Contemporary!B31,",",SUBSTITUTE(B37,",","%2c"),",",IF(Contemporary!K31<>"",Contemporary!K31,CONCATENATE(Contemporary!H31,";",Contemporary!I31)),",",Spotify!A35)),"") -> Big Yellow Taxi,Joni Mitchell,1970,Rock,115,93,76,96,68,WIP,,;pop;acoustic;alternative;retro;oldies,6wdviVWctiZnY6tVn6bh6A
A38: =IF((Contemporary!D32<>""),(CONCATENATE(Contemporary!D32,",",Contemporary!E32,",",Contemporary!G32,",",Contemporary!H32,",",Contemporary!P32,",",Contemporary!Q32,",",Contemporary!R32,",",Contemporary!T32,",",Contemporary!W32,",",Contemporary!B32,",",SUBSTITUTE(B38,",","%2c"),",",IF(Contemporary!K32<>"",Contemporary!K32,CONCATENATE(Contemporary!H32,";",Contemporary!I32)),",",Spotify!A36)),"") -> Billie Jean,Michael Jackson,1982,Pop,94,13,69,37,80,,,classic rock;psychedelic rock;,5jgFfDIR6FR0gvlA56Nakr
A39: =IF((Contemporary!#REF!<>""),(CONCATENATE(Contemporary!#REF!,",",Contemporary!#REF!,",",Contemporary!#REF!,",",Contemporary!#REF!,",",Contemporary!#REF!,",",Contemporary!#REF!,",",Contemporary!#REF!,",",Contemporary!#REF!,",",Contemporary!#REF!,",",Contemporary!#REF!,",",SUBSTITUTE(B39,",","%2c"),",",IF(Contemporary!#REF!<>"",Contemporary!#REF!,CONCATENATE(Contemporary!#REF!,";",Contemporary!#REF!)),",",Spotify!A37)),"") -> #REF!
A40: =IF((Contemporary!D33<>""),(CONCATENATE(Contemporary!D33,",",Contemporary!E33,",",Contemporary!G33,",",Contemporary!H33,",",Contemporary!P33,",",Contemporary!Q33,",",Contemporary!R33,",",Contemporary!T33,",",Contemporary!W33,",",Contemporary!B33,",",SUBSTITUTE(B40,",","%2c"),",",IF(Contemporary!K33<>"",Contemporary!K33,CONCATENATE(Contemporary!H33,";",Contemporary!I33)),",",Spotify!A38)),"") -> Bistro Fada,Stephane Wrembel,2011,Jazz,155,8,38,56,60,WIP,,folk;folk rock;instrumental;waltz,62Yu8QL1g9pdbvN4XL9Rah
A41: =IF((Contemporary!D34<>""),(CONCATENATE(Contemporary!D34,",",Contemporary!E34,",",Contemporary!G34,",",Contemporary!H34,",",Contemporary!P34,",",Contemporary!Q34,",",Contemporary!R34,",",Contemporary!T34,",",Contemporary!W34,",",Contemporary!B34,",",SUBSTITUTE(B41,",","%2c"),",",IF(Contemporary!K34<>"",Contemporary!K34,CONCATENATE(Contemporary!H34,";",Contemporary!I34)),",",Spotify!A39)),"") -> Bitter Sweet Symphony,Verve,1997,Rock,125,63,72,83,78,,,yacht rock;alternative,2BY7ALEWdloFHgQZG6VMLA
A42: =IF((Contemporary!D35<>""),(CONCATENATE(Contemporary!D35,",",Contemporary!E35,",",Contemporary!G35,",",Contemporary!H35,",",Contemporary!P35,",",Contemporary!Q35,",",Contemporary!R35,",",Contemporary!T35,",",Contemporary!W35,",",Contemporary!B35,",",SUBSTITUTE(B42,",","%2c"),",",IF(Contemporary!K35<>"",Contemporary!K35,CONCATENATE(Contemporary!H35,";",Contemporary!I35)),",",Spotify!A40)),"") -> Black Or White,Michael Jackson,1991,Pop,105,52,49,92,33,WIP,,samba;seresta;classical;chamber music;brazilian jazz;bossa nova;latin jazz;afro-cuban jazz;big band;jazz;,6MTrtNdft6F4t64fEzhNNA
A43: =IF((Contemporary!D36<>""),(CONCATENATE(Contemporary!D36,",",Contemporary!E36,",",Contemporary!G36,",",Contemporary!H36,",",Contemporary!P36,",",Contemporary!Q36,",",Contemporary!R36,",",Contemporary!T36,",",Contemporary!W36,",",Contemporary!B36,",",SUBSTITUTE(B43,",","%2c"),",",IF(Contemporary!K36<>"",Contemporary!K36,CONCATENATE(Contemporary!H36,";",Contemporary!I36)),",",Spotify!A41)),"") -> Blackbird,Beatles,1968,Folk,110,83,62,54,73,WIP,,;oldies;retro;acoustic;alternative;folk,1uzWOoJdADfstQuFtQFTUn
A44: =IF((Contemporary!D37<>""),(CONCATENATE(Contemporary!D37,",",Contemporary!E37,",",Contemporary!G37,",",Contemporary!H37,",",Contemporary!P37,",",Contemporary!Q37,",",Contemporary!R37,",",Contemporary!T37,",",Contemporary!W37,",",Contemporary!B37,",",SUBSTITUTE(B44,",","%2c"),",",IF(Contemporary!K37<>"",Contemporary!K37,CONCATENATE(Contemporary!H37,";",Contemporary!I37)),",",Spotify!A42)),"") -> Blinding Lights,Weeknd,2019,RnB,170,45,39,29,66,,,;groovy;dance;fast;love,5auMzVHFr5Zfw6IbKarZ56
A45: =IF((Contemporary!D38<>""),(CONCATENATE(Contemporary!D38,",",Contemporary!E38,",",Contemporary!G38,",",Contemporary!H38,",",Contemporary!P38,",",Contemporary!Q38,",",Contemporary!R38,",",Contemporary!T38,",",Contemporary!W38,",",Contemporary!B38,",",SUBSTITUTE(B45,",","%2c"),",",IF(Contemporary!K38<>"",Contemporary!K38,CONCATENATE(Contemporary!H38,";",Contemporary!I38)),",",Spotify!A43)),"") -> Blowin' In The Wind,Peter Paul and Mary,1962,Folk,151,58,49,91,19,,,;acoustic;oldies;retro;folk,3yrSvpt2l1xhsV9Em88Pul
A46: =IF((Contemporary!D39<>""),(CONCATENATE(Contemporary!D39,",",Contemporary!E39,",",Contemporary!G39,",",Contemporary!H39,",",Contemporary!P39,",",Contemporary!Q39,",",Contemporary!R39,",",Contemporary!T39,",",Contemporary!W39,",",Contemporary!B39,",",SUBSTITUTE(B46,",","%2c"),",",IF(Contemporary!K39<>"",Contemporary!K39,CONCATENATE(Contemporary!H39,";",Contemporary!I39)),",",Spotify!A44)),"") -> Brandy,Looking Glass,1972,Rock,128,46,72,39,83,,,;groovy;dance;fast;oldies;retro,2ixsaeFioXJmMgkkbd4uj1
A47: =IF((Contemporary!D40<>""),(CONCATENATE(Contemporary!D40,",",Contemporary!E40,",",Contemporary!G40,",",Contemporary!H40,",",Contemporary!P40,",",Contemporary!Q40,",",Contemporary!R40,",",Contemporary!T40,",",Contemporary!W40,",",Contemporary!B40,",",SUBSTITUTE(B47,",","%2c"),",",IF(Contemporary!K40<>"",Contemporary!K40,CONCATENATE(Contemporary!H40,";",Contemporary!I40)),",",Spotify!A45)),"") -> Brasileirinho,Waldir Azavedo,1947,Choro,108,66,72,80,46,WIP,,soft pop;acoustic pop;instrumental,7rrmHHc1kY9vkIZnXrcH7T
A48: =IF((Contemporary!D41<>""),(CONCATENATE(Contemporary!D41,",",Contemporary!E41,",",Contemporary!G41,",",Contemporary!H41,",",Contemporary!P41,",",Contemporary!Q41,",",Contemporary!R41,",",Contemporary!T41,",",Contemporary!W41,",",Contemporary!B41,",",SUBSTITUTE(B48,",","%2c"),",",IF(Contemporary!K41<>"",Contemporary!K41,CONCATENATE(Contemporary!H41,";",Contemporary!I41)),",",Spotify!A46)),"") -> Breakfast At Tiffany's,Deep Blue Something,1995,Rock,170,52,55,89,54,WIP,,doo-wop;love,6oRHRkQigTzJ3KwpO3XOV6
A49: =IF((Contemporary!D42<>""),(CONCATENATE(Contemporary!D42,",",Contemporary!E42,",",Contemporary!G42,",",Contemporary!H42,",",Contemporary!P42,",",Contemporary!Q42,",",Contemporary!R42,",",Contemporary!T42,",",Contemporary!W42,",",Contemporary!B42,",",SUBSTITUTE(B49,",","%2c"),",",IF(Contemporary!K42<>"",Contemporary!K42,CONCATENATE(Contemporary!H42,";",Contemporary!I42)),",",Spotify!A47)),"") -> Breathe (2 AM),Anna Nalick,2004,Folk,123,65,70,86,57,WIP,,doo-wop;adult standards;,7Gpx2fNJiilvrf9Ss8qbit
A50: =IF((Contemporary!D43<>""),(CONCATENATE(Contemporary!D43,",",Contemporary!E43,",",Contemporary!G43,",",Contemporary!H43,",",Contemporary!P43,",",Contemporary!Q43,",",Contemporary!R43,",",Contemporary!T43,",",Contemporary!W43,",",Contemporary!B43,",",SUBSTITUTE(B50,",","%2c"),",",IF(Contemporary!K43<>"",Contemporary!K43,CONCATENATE(Contemporary!H43,";",Contemporary!I43)),",",Spotify!A48)),"") -> Brown Eyed Girl,Van Morrison,1967,Rock,96,77,59,33,88,,,funk rock;alternative rock;rock;love;dance;fast;oldies;retro,48UPSzbZjgc449aqz8bxox
A51: =IF((Contemporary!D44<>""),(CONCATENATE(Contemporary!D44,",",Contemporary!E44,",",Contemporary!G44,",",Contemporary!H44,",",Contemporary!P44,",",Contemporary!Q44,",",Contemporary!R44,",",Contemporary!T44,",",Contemporary!W44,",",Contemporary!B44,",",SUBSTITUTE(B51,",","%2c"),",",IF(Contemporary!K44<>"",Contemporary!K44,CONCATENATE(Contemporary!H44,";",Contemporary!I44)),",",Spotify!A49)),"") -> Budapest,George Ezra,2013,Rock,100,29,40,34,83,,,rockabilly;rock and roll;love;dance,44AyOl4qVkzS48vBsbNXaC
...

Sheet Spotify
A1: Spotify ID | B1: Track Name | C1: Album Name | D1: Artist Name(s) | E1: Release Date | F1: Duration (ms) | G1: Popularity | H1: Added By | I1: Added At | J1: Genres | K1: Danceability | L1: Energy | M1: Key | N1: Loudness | O1: Mode | P1: Speechiness | Q1: Acousticness | R1: Instrumentalness | S1: Liveness | T1: Valence | U1: Tempo | V1: Time Signature
A3: 1BV0m40U0M4t1SLIsDnwZl | B3: 1973 | C3: All the Lost Souls | D3: James Blunt | E3: 39330 | F3: 280026 | G3: 75 | H3: 125771062 | I3: 2022-09-20T14:38:56Z | K3: 0.72 | L3: 0.668 | M3: 9 | N3: -7.928 | O3: 1 | P3: 0.0269 | Q3: 0.0653 | R3: 0.00675 | S3: 0.0789 | T3: 0.769 | U3: 123.005 | V3: 4
A4: 1pctwlBtIcKIjQMzsVcGHB | B4: A Hard Day's Night - Remastered 2015 | C4: 1 (Remastered) | D4: The Beatles | E4: 36843 | F4: 152920 | G4: 54 | H4: 125771062 | I4: 2023-07-23T10:24:47Z | J4: classic rock,psychedelic rock | K4: 0.546 | L4: 0.818 | M4: 0 | N4: -4.89 | O4: 1 | P4: 0.031 | Q4: 0.0487 | R4: 0 | S4: 0.0983 | T4: 0.756 | U4: 138.561 | V4: 4
A5: 47y8hRlWLEJ4VafE6LMjEZ | B5: A Little Less Conversation | C5: The Essential Elvis Presley | D5: Elvis Presley | E5: 2007 | F5: 121584 | G5: 56 | H5: 125771062 | I5: 2022-10-01T17:44:33Z | J5: rockabilly,rock and roll | K5: 0.584 | L5: 0.802 | M5: 2 | N5: -8.03 | O5: 1 | P5: 0.0784 | Q5: 0.149 | R5: 0 | S5: 0.0683 | T5: 0.835 | U5: 114.172 | V5: 4
A6: 3AH12fVi34vJVqriMpM6Bo | B6: A Little More | C6: Pure Fiction | D6: Eric Hutchinson | E6: 41737 | F6: 196600 | G6: 44 | H6: 125771062 | I6: 2022-09-20T14:38:56Z | K6: 0.643 | L6: 0.741 | M6: 2 | N6: -5.084 | O6: 1 | P6: 0.0404 | Q6: 0.013 | R6: 2.34e-05 | S6: 0.0711 | T6: 0.935 | U6: 80.043 | V6: 4
A7: 3RIm56NRLSZYo1xgHlbPH4 | B7: Zimmer: A Man For All Seasons | C7: Johnny English - Original Motion Picture Soundtrack | D7: Hans Zimmer;Robbie Williams | E7: 37622 | F7: 239760 | G7: 42 | H7: 125771062 | I7: 2022-09-20T14:38:56Z | J7: soundtrack,score | K7: 0.583 | L7: 0.744 | M7: 2 | N7: -8.36 | O7: 0 | P7: 0.0318 | Q7: 0.0091 | R7: 0 | S7: 0.272 | T7: 0.818 | U7: 123.901 | V7: 4
A8: 0FDzzruyVECATHXKHFs9eJ | B8: A Sky Full of Stars | C8: Ghost Stories | D8: Coldplay | E8: 41775 | F8: 267866 | G8: 88 | H8: 125771062 | I8: 2024-02-21T16:47:29Z | K8: 0.545 | L8: 0.675 | M8: 6 | N8: -6.474 | O8: 1 | P8: 0.0279 | Q8: 0.00617 | R8: 0.00197 | S8: 0.209 | T8: 0.162 | U8: 124.97 | V8: 4
A9: 4w1lzcaoZ1IC2K5TwjalRP | B9: A Thousand Miles | C9: Be Not Nobody | D9: Vanessa Carlton | E9: 37376 | F9: 237493 | G9: 83 | H9: 125771062 | I9: 2022-09-20T14:38:56Z | K9: 0.56 | L9: 0.825 | M9: 11 | N9: -3.862 | O9: 1 | P9: 0.0379 | Q9: 0.323 | R9: 0 | S9: 0.161 | T9: 0.268 | U9: 94.931 | V9: 4
A10: 6lanRgr6wXibZr8KgzXxBl | B10: a thousand years | C10: a thousand years | D10: Christina Perri | E10: 40834 | F10: 285120 | G10: 86 | H10: 125771062 | I10: 2022-09-20T14:38:56Z | J10: soft pop | K10: 0.421 | L10: 0.407 | M10: 10 | N10: -7.445 | O10: 1 | P10: 0.0267 | Q10: 0.309 | R10: 0.000961 | S10: 0.11 | T10: 0.161 | U10: 139.028 | V10: 3
A11: 69uxyAqqPIsUyTO8txoP2M | B11: Adventure of a Lifetime | C11: A Head Full of Dreams | D11: Coldplay | E11: 42342 | F11: 263786 | G11: 88 | H11: 125771062 | I11: 2022-09-20T14:38:56Z | K11: 0.638 | L11: 0.924 | M11: 7 | N11: -3.887 | O11: 1 | P11: 0.036 | Q11: 0.00205 | R11: 0.000175 | S11: 0.149 | T11: 0.53 | U11: 111.995 | V11: 4
A12: 2374M0fQpWi3dLnB54qaLX | B12: Africa | C12: Toto IV | D12: TOTO | E12: 30049 | F12: 295282 | G12: 90 | H12: 125771062 | I12: 2022-09-20T14:38:56Z | J12: yacht rock,soft rock | K12: 0.671 | L12: 0.373 | M12: 9 | N12: -18.064 | O12: 1 | P12: 0.0323 | Q12: 0.257 | R12: 8.01e-05 | S12: 0.0481 | T12: 0.732 | U12: 92.718 | V12: 4
A13: 1PC5GV3OaoXx5em8ttQOMI | B13: After Midnight | C13: Naturally | D13: J.J. Cale | E13: 1972 | F13: 143693 | G13: 62 | H13: 125771062 | I13: 2022-09-20T14:38:56Z | J13: blues,roots rock,blues rock | K13: 0.694 | L13: 0.306 | M13: 2 | N13: -19.315 | O13: 1 | P13: 0.0353 | Q13: 0.171 | R13: 0.0736 | S13: 0.0866 | T13: 0.521 | U13: 95.989 | V13: 4
A14: 7mze3mJmu79AJu8SnS37pS | B14: Aicha | C14: Bread & Barrels Of Water (International Version) | D14: Outlandish | E14: 37712 | F14: 275680 | G14: 58 | H14: 125771062 | I14: 2024-02-21T16:47:38Z | J14: dansk pop | K14: 0.745 | L14: 0.64 | M14: 2 | N14: -5.494 | O14: 1 | P14: 0.0526 | Q14: 0.21 | R14: 5.3e-05 | S14: 0.112 | T14: 0.612 | U14: 86.98 | V14: 4
A15: 5jE48hhRu8E6zBDPRSkEq7 | B15: All About That Bass | C15: Title (Deluxe) | D15: Meghan Trainor | E15: 42016 | F15: 191488 | G15: 71 | H15: 125771062 | I15: 2022-09-20T14:38:56Z | K15: 0.807 | L15: 0.887 | M15: 9 | N15: -3.726 | O15: 1 | P15: 0.0503 | Q15: 0.0573 | R15: 2.87e-06 | S15: 0.124 | T15: 0.961 | U15: 134.052 | V15: 4
A16: 0ElmwRAsaxaUZXnMbaSllH | B16: All About You | C16: Wonderland | D16: McFly | E16: 38353 | F16: 186866 | G16: 59 | H16: 125771062 | I16: 2022-09-20T14:38:56Z | K16: 0.542 | L16: 0.559 | M16: 1 | N16: -5.313 | O16: 1 | P16: 0.0258 | Q16: 0.197 | R16: 0 | S16: 0.0989 | T16: 0.295 | U16: 129.898 | V16: 4
